<?xml version="1.0"?>
<robot name="my_robot">

    <material name="grey">
        <color rgba="0.5 0.5 0.5 1" />
    </material>

    <material name="blue">
        <color rgba="0 0 0.5 1" />
    </material>

    <material name="black">
        <color rgba="0 0 0 1" />
    </material>   
    
    <!-- base_footprint (projection of base_link on the ground) -->

    <link name="base_footprint"/>
    
    <joint name="base_joint" type="fixed">
        <parent link="base_footprint"/>
        <child link="base_link"/>
        <origin xyz="0 0 0" rpy="0 0 0"/>
    </joint>
    
    <!-- base_link and base_scan (required for Nav2) -->

    <link name="base_link">
        <visual>
            <geometry>
                <box size="0.44 0.41 0.02" />
            </geometry>
            <origin xyz="0 0 0" rpy="0 0 0" />
            <material name="black" />
        </visual>
        <collision>
            <geometry>
            <box size="0.44 0.41 0.02" />
            </geometry>
            <origin xyz="0 0 0" rpy="0 0 0" />
        </collision>

    </link>
    
    <joint name="base_scan_joint" type="fixed">
        <parent link="base_link"/>
        <child link="base_scan"/>
        <origin xyz="0 0 0.086" rpy="0 0 0"/>
    </joint>
    
    <link name="base_scan">
        <visual>
            <geometry>
                <cylinder radius="0.1" length="0.06"/>
            </geometry>
            <origin xyz="0 0 0" rpy="0 0 0" />
            <material name="grey" />
        </visual>
    </link>
    
    <!-- Wheels (2 differential wheels + 1 caster wheel to keep the balance) -->
    
    <joint name="left_wheel_joint" type="continuous">
        <parent link="base_link"/>
        <child link="left_wheel"/>
        <origin xyz="-0.14 0.255 0" rpy="0 0 0"/>
        <axis xyz="0 1 0"/>
    </joint>

    <link name="left_wheel">
        <visual>
            <geometry>
                <cylinder radius="0.086" length="0.05"/>
            </geometry>
            <origin xyz="0 0 0" rpy="1.57 0 0" />
            <material name="grey" />
        </visual>
    </link>
    
    <joint name="right_wheel_joint" type="continuous">
        <parent link="base_link"/>
        <child link="right_wheel"/>
        <origin xyz="-0.14 -0.255 0" rpy="0 0 0"/>
        <axis xyz="0 1 0"/>
    </joint>

    <link name="right_wheel">
        <visual>
            <geometry>
		    <cylinder radius="0.086" length="0.05"/>
            </geometry>
            <origin xyz="0 0 0" rpy="1.57 0 0" />
            <material name="grey" />
        </visual>
    </link>
    
    <joint name="caster_wheel_joint" type="fixed">
        <parent link="base_link"/>
        <child link="caster_wheel"/>
        <origin xyz="0.23 0 -0.05" rpy="0 0 0"/>
    </joint>

    <link name="caster_wheel">
        <visual>
            <geometry>
                <sphere radius="0.04"/>
            </geometry>
            <origin xyz="0 0 0" rpy="0 0 0" />
            <material name="grey" />
        </visual>
    </link>

    <joint name="imu_joint" type="fixed">
        <parent link="base_link"/>
        <child link="imu_link"/>
        <origin xyz="0.23 0 0.025" rpy="0 0 0"/>
    </joint>

    <link name="imu_link">
        <visual>
            <geometry>
                <box size="0.01 0.02 0.01"/>
            </geometry>
            <origin xyz="0 0 0" rpy="0 0 0" />
	    <material name="blue"/>
        </visual>
    </link>


    <ros2_control name="differential_drive_robot" type="system">
        <hardware>
        <!--
            <plugin>your_robot_hardware/DiffDriveHardware</plugin>
            <param name="serial_port">/dev/ttyUSB0</param>
            <param name="baud_rate">115200</param>
        -->
            <plugin>mock_components/GenericSystem</plugin>
            <param name="mock_sensor_commands">false</param>
            <param name="state_following_offset">0.0</param>
        </hardware>
        <joint name="left_wheel_joint">
            <command_interface name="velocity"/>
            <state_interface name="position"/>
            <state_interface name="velocity"/>
        </joint>
            <joint name="right_wheel_joint">
	        <command_interface name="velocity"/>
    	    <state_interface name="position"/>
    	    <state_interface name="velocity"/>
        </joint>
    </ros2_control>

    <gazebo>
        <plugin filename = "libgazevo_ros2_control.so" name ="gazebo_ros2_control">
            <parameters>$(find launch_paxi_controller)/controller/paxi_controller.yaml</parameters>
        </plugin>
    </gazebo>

</robot>


